Workbook
Name Orders: Orders!$A$1:$U$9995
Name People: People!$A$1:$B$5
Name Returns: Returns!$B$1:$B$801
Name ВстроеннаяВременнаяШкала_Order_Date: #N/A
Name Срез_Category: #N/A
Name Срез_Region: #N/A
Name Срез_Segment: #N/A
Name Срез_Sub_Category: #N/A

Sheet Содержание
A1: SUPERSTORE CONTENTS
B4: Дашборд
B6: Таблица Заказов
B8: Таблица Рег. Менеджеров
B10: Таблица Возвратов
B12: Динамика Продаж и Прибыли
B14: Продажи по Категориям
B16: Продажи по Рег.Менеджерам
B18: Продажи по Сегментам
B20: Общие показатели
B22: Динамика по Сегментам
B24: Продажи по Штатам
B26: Продажи по Регионам
B28: Процент Возвратов

Sheet Dashboard
A1: SUPERSTORE DASHBOARD
O2: КЛЮЧЕВЫЕ МЕТРИКИ
O3: Продажи | P3: =SUM('Общие показатели'!C:C) -> 2297200.9
O4: Прибыль | P4: =SUM('Общие показатели'!D:D) -> 286397.02
O5: Коэф прибыли | P5: =P4/P3 -> 0.12467217
O6: Скидка | P6: =AVERAGE('Общие показатели'!E:E) -> 0.12469859

Sheet Orders
A1: Row ID | B1: Order ID | C1: Order Date | D1: Ship Date | E1: Ship Mode | F1: Customer ID | G1: Customer Name | H1: Segment | I1: Country | J1: City | K1: State | L1: Postal Code | M1: Region | N1: Product ID | O1: Category | P1: Sub-Category | Q1: Product Name | R1: Sales | S1: Quantity | T1: Discount | U1: Profit | V1: Person | W1: Returned
A2: 1 | B2: CA-2018-152156 | C2: 43412 | D2: 43415 | E2: Second Class | F2: CG-12520 | G2: Claire Gute | H2: Consumer | I2: United States | J2: Henderson | K2: Kentucky | L2: 42420 | M2: South | N2: FUR-BO-10001798 | O2: Furniture | P2: Bookcases | Q2: Bush Somerset Collection Bookcase | R2: 261.96 | S2: 2 | T2: 0 | U2: 41.9136 | V2: =VLOOKUP(M2,People!$A$2:$B$5, 2, 0) -> Cassandra Brandow | W2: =IFERROR(VLOOKUP(Data[[#This Row],[Order ID]],Returns!$A$2:$B$801, 2, 0), "No") -> No
A3: 2 | B3: CA-2018-152156 | C3: 43412 | D3: 43415 | E3: Second Class | F3: CG-12520 | G3: Claire Gute | H3: Consumer | I3: United States | J3: Henderson | K3: Kentucky | L3: 42420 | M3: South | N3: FUR-CH-10000454 | O3: Furniture | P3: Chairs | Q3: Hon Deluxe Fabric Upholstered Stacking Chairs, Rounded Back | R3: 731.94 | S3: 3 | T3: 0 | U3: 219.582 | V3: =VLOOKUP(M3,People!$A$2:$B$5, 2, 0) -> Cassandra Brandow | W3: =IFERROR(VLOOKUP(Data[[#This Row],[Order ID]],Returns!$A$2:$B$801, 2, 0), "No") -> No
A4: 3 | B4: CA-2018-138688 | C4: 43263 | D4: 43267 | E4: Second Class | F4: DV-13045 | G4: Darrin Van Huff | H4: Corporate | I4: United States | J4: Los Angeles | K4: California | L4: 90036 | M4: West | N4: OFF-LA-10000240 | O4: Office Supplies | P4: Labels | Q4: Self-Adhesive Address Labels for Typewriters by Universal | R4: 14.62 | S4: 2 | T4: 0 | U4: 6.8714 | V4: =VLOOKUP(M4,People!$A$2:$B$5, 2, 0) -> Anna Andreadi | W4: =IFERROR(VLOOKUP(Data[[#This Row],[Order ID]],Returns!$A$2:$B$801, 2, 0), "No") -> No
A5: 4 | B5: US-2017-108966 | C5: 43019 | D5: 43026 | E5: Standard Class | F5: SO-20335 | G5: Sean O'Donnell | H5: Consumer | I5: United States | J5: Fort Lauderdale | K5: Florida | L5: 33311 | M5: South | N5: FUR-TA-10000577 | O5: Furniture | P5: Tables | Q5: Bretford CR4500 Series Slim Rectangular Table | R5: 957.5775 | S5: 5 | T5: 0.45 | U5: -383.031 | V5: =VLOOKUP(M5,People!$A$2:$B$5, 2, 0) -> Cassandra Brandow | W5: =IFERROR(VLOOKUP(Data[[#This Row],[Order ID]],Returns!$A$2:$B$801, 2, 0), "No") -> No
A6: 5 | B6: US-2017-108966 | C6: 43019 | D6: 43026 | E6: Standard Class | F6: SO-20335 | G6: Sean O'Donnell | H6: Consumer | I6: United States | J6: Fort Lauderdale | K6: Florida | L6: 33311 | M6: South | N6: OFF-ST-10000760 | O6: Office Supplies | P6: Storage | Q6: Eldon Fold 'N Roll Cart System | R6: 22.368 | S6: 2 | T6: 0.2 | U6: 2.5164 | V6: =VLOOKUP(M6,People!$A$2:$B$5, 2, 0) -> Cassandra Brandow | W6: =IFERROR(VLOOKUP(Data[[#This Row],[Order ID]],Returns!$A$2:$B$801, 2, 0), "No") -> No
A7: 6 | B7: CA-2016-115812 | C7: 42530 | D7: 42535 | E7: Standard Class | F7: BH-11710 | G7: Brosina Hoffman | H7: Consumer | I7: United States | J7: Los Angeles | K7: California | L7: 90032 | M7: West | N7: FUR-FU-10001487 | O7: Furniture | P7: Furnishings | Q7: Eldon Expressions Wood and Plastic Desk Accessories, Cherry Wood | R7: 48.86 | S7: 7 | T7: 0 | U7: 14.1694 | V7: =VLOOKUP(M7,People!$A$2:$B$5, 2, 0) -> Anna Andreadi | W7: =IFERROR(VLOOKUP(Data[[#This Row],[Order ID]],Returns!$A$2:$B$801, 2, 0), "No") -> No
A8: 7 | B8: CA-2016-115812 | C8: 42530 | D8: 42535 | E8: Standard Class | F8: BH-11710 | G8: Brosina Hoffman | H8: Consumer | I8: United States | J8: Los Angeles | K8: California | L8: 90032 | M8: West | N8: OFF-AR-10002833 | O8: Office Supplies | P8: Art | Q8: Newell 322 | R8: 7.28 | S8: 4 | T8: 0 | U8: 1.9656 | V8: =VLOOKUP(M8,People!$A$2:$B$5, 2, 0) -> Anna Andreadi | W8: =IFERROR(VLOOKUP(Data[[#This Row],[Order ID]],Returns!$A$2:$B$801, 2, 0), "No") -> No
A9: 8 | B9: CA-2016-115812 | C9: 42530 | D9: 42535 | E9: Standard Class | F9: BH-11710 | G9: Brosina Hoffman | H9: Consumer | I9: United States | J9: Los Angeles | K9: California | L9: 90032 | M9: West | N9: TEC-PH-10002275 | O9: Technology | P9: Phones | Q9: Mitel 5320 IP Phone VoIP phone | R9: 907.152 | S9: 6 | T9: 0.2 | U9: 90.7152 | V9: =VLOOKUP(M9,People!$A$2:$B$5, 2, 0) -> Anna Andreadi | W9: =IFERROR(VLOOKUP(Data[[#This Row],[Order ID]],Returns!$A$2:$B$801, 2, 0), "No") -> No
A10: 9 | B10: CA-2016-115812 | C10: 42530 | D10: 42535 | E10: Standard Class | F10: BH-11710 | G10: Brosina Hoffman | H10: Consumer | I10: United States | J10: Los Angeles | K10: California | L10: 90032 | M10: West | N10: OFF-BI-10003910 | O10: Office Supplies | P10: Binders | Q10: DXL Angle-View Binders with Locking Rings by Samsill | R10: 18.504 | S10: 3 | T10: 0.2 | U10: 5.7825 | V10: =VLOOKUP(M10,People!$A$2:$B$5, 2, 0) -> Anna Andreadi | W10: =IFERROR(VLOOKUP(Data[[#This Row],[Order ID]],Returns!$A$2:$B$801, 2, 0), "No") -> No
A11: 10 | B11: CA-2016-115812 | C11: 42530 | D11: 42535 | E11: Standard Class | F11: BH-11710 | G11: Brosina Hoffman | H11: Consumer | I11: United States | J11: Los Angeles | K11: California | L11: 90032 | M11: West | N11: OFF-AP-10002892 | O11: Office Supplies | P11: Appliances | Q11: Belkin F5C206VTEL 6 Outlet Surge | R11: 114.9 | S11: 5 | T11: 0 | U11: 34.47 | V11: =VLOOKUP(M11,People!$A$2:$B$5, 2, 0) -> Anna Andreadi | W11: =IFERROR(VLOOKUP(Data[[#This Row],[Order ID]],Returns!$A$2:$B$801, 2, 0), "No") -> No
A12: 11 | B12: CA-2016-115812 | C12: 42530 | D12: 42535 | E12: Standard Class | F12: BH-11710 | G12: Brosina Hoffman | H12: Consumer | I12: United States | J12: Los Angeles | K12: California | L12: 90032 | M12: West | N12: FUR-TA-10001539 | O12: Furniture | P12: Tables | Q12: Chromcraft Rectangular Conference Tables | R12: 1706.184 | S12: 9 | T12: 0.2 | U12: 85.3092 | V12: =VLOOKUP(M12,People!$A$2:$B$5, 2, 0) -> Anna Andreadi | W12: =IFERROR(VLOOKUP(Data[[#This Row],[Order ID]],Returns!$A$2:$B$801, 2, 0), "No") -> No
A13: 12 | B13: CA-2016-115812 | C13: 42530 | D13: 42535 | E13: Standard Class | F13: BH-11710 | G13: Brosina Hoffman | H13: Consumer | I13: United States | J13: Los Angeles | K13: California | L13: 90032 | M13: West | N13: TEC-PH-10002033 | O13: Technology | P13: Phones | Q13: Konftel 250 Conference phone - Charcoal black | R13: 911.424 | S13: 4 | T13: 0.2 | U13: 68.3568 | V13: =VLOOKUP(M13,People!$A$2:$B$5, 2, 0) -> Anna Andreadi | W13: =IFERROR(VLOOKUP(Data[[#This Row],[Order ID]],Returns!$A$2:$B$801, 2, 0), "No") -> No
... A2235: 2234 | B2235: CA-2017-123232 | C2235: 43083 | D2235: 43085 | E2235: Second Class | F2235: DJ-13630 | G2235: Doug Jacobs | H2235: Consumer | I2235: United States | J2235: Portland | K2235: Oregon | L2235: 97206 | M2235: West | N2235: TEC-PH-10001051 | O2235: Technology | P2235: Phones | Q2235: HTC One | R2235: 319.968 | S2235: 4 | T2235: 0.2 | U2235: 35.9964 | V2235: =VLOOKUP(M2235,People!$A$2:$B$5, 2, 0) -> Anna Andreadi | W2235: =IFERROR(VLOOKUP(Data[[#This Row],[Order ID]],Returns!$A$2:$B$801, 2, 0), "No") -> No
A2236: 2235 | B2236: CA-2019-104066 | C2236: 43804 | D2236: 43809 | E2236: Standard Class | F2236: QJ-19255 | G2236: Quincy Jones | H2236: Corporate | I2236: United States | J2236: Burlington | K2236: Vermont | M2236: East | N2236: TEC-AC-10001013 | O2236: Technology | P2236: Accessories | Q2236: Logitech ClearChat Comfort/USB Headset H390 | R2236: 205.03 | S2236: 7 | T2236: 0 | U2236: 67.6599 | V2236: =VLOOKUP(M2236,People!$A$2:$B$5, 2, 0) -> Chuck Magee | W2236: =IFERROR(VLOOKUP(Data[[#This Row],[Order ID]],Returns!$A$2:$B$801, 2, 0), "No") -> No
A2237: 2236 | B2237: CA-2017-145849 | C2237: 42993 | D2237: 42995 | E2237: Second Class | F2237: CT-11995 | G2237: Carol Triggs | H2237: Consumer | I2237: United States | J2237: Indianapolis | K2237: Indiana | L2237: 46203 | M2237: Central | N2237: OFF-ST-10000025 | O2237: Office Supplies | P2237: Storage | Q2237: Fellowes Stor/Drawer Steel Plus Storage Drawers | R2237: 190.86 | S2237: 2 | T2237: 0 | U2237: 11.4516 | V2237: =VLOOKUP(M2237,People!$A$2:$B$5, 2, 0) -> Kelly Williams | W2237: =IFERROR(VLOOKUP(Data[[#This Row],[Order ID]],Returns!$A$2:$B$801, 2, 0), "No") -> No
A2238: 2237 | B2238: CA-2017-145849 | C2238: 42993 | D2238: 42995 | E2238: Second Class | F2238: CT-11995 | G2238: Carol Triggs | H2238: Consumer | I2238: United States | J2238: Indianapolis | K2238: Indiana | L2238: 46203 | M2238: Central | N2238: OFF-AR-10000817 | O2238: Office Supplies | P2238: Art | Q2238: Manco Dry-Lighter Erasable Highlighter | R2238: 24.32 | S2238: 8 | T2238: 0 | U2238: 8.2688 | V2238: =VLOOKUP(M2238,People!$A$2:$B$5, 2, 0) -> Kelly Williams | W2238: =IFERROR(VLOOKUP(Data[[#This Row],[Order ID]],Returns!$A$2:$B$801, 2, 0), "No") -> No
A2239: 2238 | B2239: CA-2018-122322 | C2239: 43296 | D2239: 43302 | E2239: Standard Class | F2239: RH-19510 | G2239: Rick Huthwaite | H2239: Home Office | I2239: United States | J2239: Provo | K2239: Utah | L2239: 84604 | M2239: West | N2239: OFF-SU-10000952 | O2239: Office Supplies | P2239: Supplies | Q2239: Fiskars Home & Office Scissors | R2239: 44.4 | S2239: 5 | T2239: 0 | U2239: 12.432 | V2239: =VLOOKUP(M2239,People!$A$2:$B$5, 2, 0) -> Anna Andreadi | W2239: =IFERROR(VLOOKUP(Data[[#This Row],[Order ID]],Returns!$A$2:$B$801, 2, 0), "No") -> No
A2240: 2239 | B2240: CA-2019-166849 | C2240: 43575 | D2240: 43581 | E2240: Standard Class | F2240: SJ-20125 | G2240: Sanjit Jacobs | H2240: Home Office | I2240: United States | J2240: Chicago | K2240: Illinois | L2240: 60610 | M2240: Central | N2240: FUR-FU-10004597 | O2240: Furniture | P2240: Furnishings | Q2240: Eldon Cleatmat Chair Mats for Medium Pile Carpets | R2240: 44.4 | S2240: 2 | T2240: 0.6 | U2240: -52.17 | V2240: =VLOOKUP(M2240,People!$A$2:$B$5, 2, 0) -> Kelly Williams | W2240: =IFERROR(VLOOKUP(Data[[#This Row],[Order ID]],Returns!$A$2:$B$801, 2, 0), "No") -> No
A2241: 2240 | B2241: CA-2018-146633 | C2241: 43419 | D2241: 43421 | E2241: Second Class | F2241: TG-21310 | G2241: Toby Gnade | H2241: Consumer | I2241: United States | J2241: Los Angeles | K2241: California | L2241: 90049 | M2241: West | N2241: OFF-BI-10003527 | O2241: Office Supplies | P2241: Binders | Q2241: Fellowes PB500 Electric Punch Plastic Comb Binding Machine with Manual Bind | R2241: 1016.792 | S2241: 1 | T2241: 0.2 | U2241: 381.297 | V2241: =VLOOKUP(M2241,People!$A$2:$B$5, 2, 0) -> Anna Andreadi | W2241: =IFERROR(VLOOKUP(Data[[#This Row],[Order ID]],Returns!$A$2:$B$801, 2, 0), "No") -> No
A2242: 2241 | B2242: CA-2018-146633 | C2242: 43419 | D2242: 43421 | E2242: Second Class | F2242: TG-21310 | G2242: Toby Gnade | H2242: Consumer | I2242: United States | J2242: Los Angeles | K2242: California | L2242: 90049 | M2242: West | N2242: OFF-BI-10002982 | O2242: Office Supplies | P2242: Binders | Q2242: Avery Self-Adhesive Photo Pockets for Polaroid Photos | R2242: 38.136 | S2242: 7 | T2242: 0.2 | U2242: 13.3476 | V2242: =VLOOKUP(M2242,People!$A$2:$B$5, 2, 0) -> Anna Andreadi | W2242: =IFERROR(VLOOKUP(Data[[#This Row],[Order ID]],Returns!$A$2:$B$801, 2, 0), "No") -> No
A2243: 2242 | B2243: US-2018-126893 | C2243: 43430 | D2243: 43435 | E2243: Standard Class | F2243: CT-11995 | G2243: Carol Triggs | H2243: Consumer | I2243: United States | J2243: Philadelphia | K2243: Pennsylvania | L2243: 19134 | M2243: East | N2243: TEC-PH-10004165 | O2243: Technology | P2243: Phones | Q2243: Mitel MiVoice 5330e IP Phone | R2243: 494.982 | S2243: 3 | T2243: 0.4 | U2243: -115.4958 | V2243: =VLOOKUP(M2243,People!$A$2:$B$5, 2, 0) -> Chuck Magee | W2243: =IFERROR(VLOOKUP(Data[[#This Row],[Order ID]],Returns!$A$2:$B$801, 2, 0), "No") -> No
A2244: 2243 | B2244: CA-2019-103380 | C2244: 43790 | D2244: 43794 | E2244: Standard Class | F2244: BF-11005 | G2244: Barry Franz | H2244: Home Office | I2244: United States | J2244: Pasadena | K2244: California | L2244: 91104 | M2244: West | N2244: OFF-ST-10003442 | O2244: Office Supplies | P2244: Storage | Q2244: Eldon Portable Mobile Manager | R2244: 56.56 | S2244: 2 | T2244: 0 | U2244: 15.2712 | V2244: =VLOOKUP(M2244,People!$A$2:$B$5, 2, 0) -> Anna Andreadi | W2244: =IFERROR(VLOOKUP(Data[[#This Row],[Order ID]],Returns!$A$2:$B$801, 2, 0), "No") -> Yes
A2245: 2244 | B2245: CA-2019-103380 | C2245: 43790 | D2245: 43794 | E2245: Standard Class | F2245: BF-11005 | G2245: Barry Franz | H2245: Home Office | I2245: United States | J2245: Pasadena | K2245: California | L2245: 91104 | M2245: West | N2245: OFF-AR-10003856 | O2245: Office Supplies | P2245: Art | Q2245: Newell 344 | R2245: 5.56 | S2245: 2 | T2245: 0 | U2245: 1.4456 | V2245: =VLOOKUP(M2245,People!$A$2:$B$5, 2, 0) -> Anna Andreadi | W2245: =IFERROR(VLOOKUP(Data[[#This Row],[Order ID]],Returns!$A$2:$B$801, 2, 0), "No") -> Yes
A2246: 2245 | B2246: CA-2019-103380 | C2246: 43790 | D2246: 43794 | E2246: Standard Class | F2246: BF-11005 | G2246: Barry Franz | H2246: Home Office | I2246: United States | J2246: Pasadena | K2246: California | L2246: 91104 | M2246: West | N2246: OFF-FA-10004248 | O2246: Office Supplies | P2246: Fasteners | Q2246: Advantus T-Pin Paper Clips | R2246: 9.02 | S2246: 2 | T2246: 0 | U2246: 3.5178 | V2246: =VLOOKUP(M2246,People!$A$2:$B$5, 2, 0) -> Anna Andreadi | W2246: =IFERROR(VLOOKUP(Data[[#This Row],[Order ID]],Returns!$A$2:$B$801, 2, 0), "No") -> Yes
A2247: 2246 | B2247: CA-2019-103380 | C2247: 43790 | D2247: 43794 | E2247: Standard Class | F2247: BF-11005 | G2247: Barry Franz | H2247: Home Office | I2247: United States | J2247: Pasadena | K2247: California | L2247: 91104 | M2247: West | N2247: OFF-AP-10001492 | O2247: Office Supplies | P2247: Appliances | Q2247: Acco Six-Outlet Power Strip, 4' Cord Length | R2247: 8.62 | S2247: 1 | T2247: 0 | U2247: 2.2412 | V2247: =VLOOKUP(M2247,People!$A$2:$B$5, 2, 0) -> Anna Andreadi | W2247: =IFERROR(VLOOKUP(Data[[#This Row],[Order ID]],Returns!$A$2:$B$801, 2, 0), "No") -> Yes
A2248: 2247 | B2248: CA-2019-103380 | C2248: 43790 | D2248: 43794 | E2248: Standard Class | F2248: BF-11005 | G2248: Barry Franz | H2248: Home Office | I2248: United States | J2248: Pasadena | K2248: California | L2248: 91104 | M2248: West | N2248: TEC-PH-10004165 | O2248: Technology | P2248: Phones | Q2248: Mitel MiVoice 5330e IP Phone | R2248: 659.976 | S2248: 3 | T2248: 0.2 | U2248: 49.4982 | V2248: =VLOOKUP(M2248,People!$A$2:$B$5, 2, 0) -> Anna Andreadi | W2248: =IFERROR(VLOOKUP(Data[[#This Row],[Order ID]],Returns!$A$2:$B$801, 2, 0), "No") -> Yes
... A5275: 5274 | B5275: US-2018-158309 | C5275: 43430 | D5275: 43433 | E5275: First Class | F5275: PA-19060 | G5275: Pete Armstrong | H5275: Home Office | I5275: United States | J5275: Miami | K5275: Florida | L5275: 33142 | M5275: South | N5275: OFF-BI-10000145 | O5275: Office Supplies | P5275: Binders | Q5275: Zipper Ring Binder Pockets | R5275: 3.744 | S5275: 4 | T5275: 0.7 | U5275: -2.6208 | V5275: =VLOOKUP(M5275,People!$A$2:$B$5, 2, 0) -> Cassandra Brandow | W5275: =IFERROR(VLOOKUP(Data[[#This Row],[Order ID]],Returns!$A$2:$B$801, 2, 0), "No") -> No
A5276: 5275 | B5276: CA-2017-162887 | C5276: 43046 | D5276: 43048 | E5276: Second Class | F5276: SV-20785 | G5276: Stewart Visinsky | H5276: Consumer | I5276: United States | J5276: Burlington | K5276: Vermont | M5276: East | N5276: FUR-CH-10000595 | O5276: Furniture | P5276: Chairs | Q5276: Safco Contoured Stacking Chairs | R5276: 715.2 | S5276: 3 | T5276: 0 | U5276: 178.8 | V5276: =VLOOKUP(M5276,People!$A$2:$B$5, 2, 0) -> Chuck Magee | W5276: =IFERROR(VLOOKUP(Data[[#This Row],[Order ID]],Returns!$A$2:$B$801, 2, 0), "No") -> No
A5277: 5276 | B5277: CA-2019-147333 | C5277: 43813 | D5277: 43819 | E5277: Standard Class | F5277: KL-16555 | G5277: Kelly Lampkin | H5277: Corporate | I5277: United States | J5277: Fayetteville | K5277: Arkansas | L5277: 72701 | M5277: South | N5277: TEC-AC-10004469 | O5277: Technology | P5277: Accessories | Q5277: Microsoft Sculpt Comfort Mouse | R5277: 159.8 | S5277: 4 | T5277: 0 | U5277: 70.312 | V5277: =VLOOKUP(M5277,People!$A$2:$B$5, 2, 0) -> Cassandra Brandow | W5277: =IFERROR(VLOOKUP(Data[[#This Row],[Order ID]],Returns!$A$2:$B$801, 2, 0), "No") -> No
A5278: 5277 | B5278: CA-2019-147333 | C5278: 43813 | D5278: 43819 | E5278: Standard Class | F5278: KL-16555 | G5278: Kelly Lampkin | H5278: Corporate | I5278: United States | J5278: Fayetteville | K5278: Arkansas | L5278: 72701 | M5278: South | N5278: TEC-AC-10003038 | O5278: Technology | P5278: Accessories | Q5278: Kingston Digital DataTraveler 16GB USB 2.0 | R5278: 44.75 | S5278: 5 | T5278: 0 | U5278: 8.5025 | V5278: =VLOOKUP(M5278,People!$A$2:$B$5, 2, 0) -> Cassandra Brandow | W5278: =IFERROR(VLOOKUP(Data[[#This Row],[Order ID]],Returns!$A$2:$B$801, 2, 0), "No") -> No
A5279: 5278 | B5279: CA-2016-113859 | C5279: 42626 | D5279: 42630 | E5279: Standard Class | F5279: BC-11125 | G5279: Becky Castell | H5279: Home Office | I5279: United States | J5279: Odessa | K5279: Texas | L5279: 79762 | M5279: Central | N5279: FUR-CH-10004698 | O5279: Furniture | P5279: Chairs | Q5279: Padded Folding Chairs, Black, 4/Carton | R5279: 340.116 | S5279: 6 | T5279: 0.3 | U5279: -9.7176 | V5279: =VLOOKUP(M5279,People!$A$2:$B$5, 2, 0) -> Kelly Williams | W5279: =IFERROR(VLOOKUP(Data[[#This Row],[Order ID]],Returns!$A$2:$B$801, 2, 0), "No") -> No
A5280: 5279 | B5280: CA-2016-159681 | C5280: 42711 | D5280: 42717 | E5280: Standard Class | F5280: PO-18850 | G5280: Patrick O'Brill | H5280: Consumer | I5280: United States | J5280: Virginia Beach | K5280: Virginia | L5280: 23464 | M5280: South | N5280: OFF-PA-10003641 | O5280: Office Supplies | P5280: Paper | Q5280: Xerox 1909 | R5280: 105.52 | S5280: 4 | T5280: 0 | U5280: 48.5392 | V5280: =VLOOKUP(M5280,People!$A$2:$B$5, 2, 0) -> Cassandra Brandow | W5280: =IFERROR(VLOOKUP(Data[[#This Row],[Order ID]],Returns!$A$2:$B$801, 2, 0), "No") -> No
A5281: 5280 | B5281: US-2019-104094 | C5281: 43715 | D5281: 43719 | E5281: Standard Class | F5281: AG-10675 | G5281: Anna Gayman | H5281: Consumer | I5281: United States | J5281: Milwaukee | K5281: Wisconsin | L5281: 53209 | M5281: Central | N5281: TEC-AC-10002134 | O5281: Technology | P5281: Accessories | Q5281: Rosewill 107 Normal Keys USB Wired Standard Keyboard | R5281: 13.48 | S5281: 1 | T5281: 0 | U5281: 1.8872 | V5281: =VLOOKUP(M5281,People!$A$2:$B$5, 2, 0) -> Kelly Williams | W5281: =IFERROR(VLOOKUP(Data[[#This Row],[Order ID]],Returns!$A$2:$B$801, 2, 0), "No") -> No
A5282: 5281 | B5282: CA-2019-152709 | C5282: 43745 | D5282: 43750 | E5282: Standard Class | F5282: DB-13210 | G5282: Dean Braden | H5282: Consumer | I5282: United States | J5282: Detroit | K5282: Michigan | L5282: 48234 | M5282: Central | N5282: OFF-ST-10001837 | O5282: Office Supplies | P5282: Storage | Q5282: SAFCO Mobile Desk Side File, Wire Frame | R5282: 85.52 | S5282: 2 | T5282: 0 | U5282: 22.2352 | V5282: =VLOOKUP(M5282,People!$A$2:$B$5, 2, 0) -> Kelly Williams | W5282: =IFERROR(VLOOKUP(Data[[#This Row],[Order ID]],Returns!$A$2:$B$801, 2, 0), "No") -> No
A5283: 5282 | B5283: CA-2017-105158 | C5283: 42983 | D5283: 42988 | E5283: Standard Class | F5283: SP-20860 | G5283: Sung Pak | H5283: Corporate | I5283: United States | J5283: Rochester | K5283: Minnesota | L5283: 55901 | M5283: Central | N5283: FUR-FU-10001706 | O5283: Furniture | P5283: Furnishings | Q5283: Longer-Life Soft White Bulbs | R5283: 6.16 | S5283: 2 | T5283: 0 | U5283: 2.9568 | V5283: =VLOOKUP(M5283,People!$A$2:$B$5, 2, 0) -> Kelly Williams | W5283: =IFERROR(VLOOKUP(Data[[#This Row],[Order ID]],Returns!$A$2:$B$801, 2, 0), "No") -> Yes
A5284: 5283 | B5284: CA-2017-105158 | C5284: 42983 | D5284: 42988 | E5284: Standard Class | F5284: SP-20860 | G5284: Sung Pak | H5284: Corporate | I5284: United States | J5284: Rochester | K5284: Minnesota | L5284: 55901 | M5284: Central | N5284: OFF-PA-10001970 | O5284: Office Supplies | P5284: Paper | Q5284: Xerox 1881 | R5284: 36.84 | S5284: 3 | T5284: 0 | U5284: 17.3148 | V5284: =VLOOKUP(M5284,People!$A$2:$B$5, 2, 0) -> Kelly Williams | W5284: =IFERROR(VLOOKUP(Data[[#This Row],[Order ID]],Returns!$A$2:$B$801, 2, 0), "No") -> Yes
A5285: 5284 | B5285: CA-2016-133424 | C5285: 42459 | D5285: 42464 | E5285: Standard Class | F5285: Dl-13600 | G5285: Dorris liebe | H5285: Corporate | I5285: United States | J5285: Seattle | K5285: Washington | L5285: 98105 | M5285: West | N5285: OFF-ST-10002957 | O5285: Office Supplies | P5285: Storage | Q5285: Sterilite Show Offs Storage Containers | R5285: 15.84 | S5285: 3 | T5285: 0 | U5285: 0 | V5285: =VLOOKUP(M5285,People!$A$2:$B$5, 2, 0) -> Anna Andreadi | W5285: =IFERROR(VLOOKUP(Data[[#This Row],[Order ID]],Returns!$A$2:$B$801, 2, 0), "No") -> No
A5286: 5285 | B5286: CA-2016-133424 | C5286: 42459 | D5286: 42464 | E5286: Standard Class | F5286: Dl-13600 | G5286: Dorris liebe | H5286: Corporate | I5286: United States | J5286: Seattle | K5286: Washington | L5286: 98105 | M5286: West | N5286: OFF-LA-10002312 | O5286: Office Supplies | P5286: Labels | Q5286: Avery 490 | R5286: 44.4 | S5286: 3 | T5286: 0 | U5286: 22.2 | V5286: =VLOOKUP(M5286,People!$A$2:$B$5, 2, 0) -> Anna Andreadi | W5286: =IFERROR(VLOOKUP(Data[[#This Row],[Order ID]],Returns!$A$2:$B$801, 2, 0), "No") -> No
A5287: 5286 | B5287: CA-2019-105991 | C5287: 43590 | D5287: 43591 | E5287: First Class | F5287: LH-17020 | G5287: Lisa Hazard | H5287: Consumer | I5287: United States | J5287: Louisville | K5287: Colorado | L5287: 80027 | M5287: West | N5287: OFF-EN-10002600 | O5287: Office Supplies | P5287: Envelopes | Q5287: Redi-Strip #10 Envelopes, 4 1/8 x 9 1/2 | R5287: 21.24 | S5287: 9 | T5287: 0.2 | U5287: 7.434 | V5287: =VLOOKUP(M5287,People!$A$2:$B$5, 2, 0) -> Anna Andreadi | W5287: =IFERROR(VLOOKUP(Data[[#This Row],[Order ID]],Returns!$A$2:$B$801, 2, 0), "No") -> No
...

Sheet People
A1: Region | B1: Person
A2: Central | B2: Kelly Williams
A3: East | B3: Chuck Magee
A4: South | B4: Cassandra Brandow
A5: West | B5: Anna Andreadi

Sheet Returns
A1: Order ID | B1: Returned
A2: CA-2016-100762 | B2: Yes
A3: CA-2016-100762 | B3: Yes
A4: CA-2016-100762 | B4: Yes
A5: CA-2016-100762 | B5: Yes
A6: CA-2016-100867 | B6: Yes
A7: CA-2016-102652 | B7: Yes
A8: CA-2016-102652 | B8: Yes
A9: CA-2016-102652 | B9: Yes
A10: CA-2016-102652 | B10: Yes
A11: CA-2016-103373 | B11: Yes
A12: CA-2016-103744 | B12: Yes
... A801: US-2019-155999 | B801: Yes

Sheet Продажи, прибыль
A2: Проффит-Сейлс
B3: Данные
A4: Названия строк | B4: Сумма по полю Sales | C4: Сумма по полю Profit
A5: 2016 | B5: 484247.5 | C5: 49543.974
A6: янв | B6: 14236.895 | C6: 2450.1907
A7: фев | B7: 4519.892 | C7: 862.3084
A8: мар | B8: 55691.009 | C8: 498.7299
A9: апр | B9: 28295.345 | C9: 3488.8352
A10: май | B10: 23648.287 | C10: 2738.7096
A11: июн | B11: 34595.128 | C11: 4976.5244
A12: июл | B12: 33946.393 | C12: -841.4826
A13: авг | B13: 27909.468 | C13: 5318.105
A14: сен | B14: 81777.351 | C14: 8328.0994
A15: окт | B15: 31453.393 | C15: 3448.2573
A16: ноя | B16: 78628.717 | C16: 9292.1269
... A57: Общий итог | B57: 2297200.9 | C57: 286397.02

Sheet Категории
A2: Проффит-Сейлс по категориям
B3: Данные
A4: Названия строк | B4: Сумма по полю Sales | C4: Сумма по полю Profit
A5: Furniture | B5: 741999.8 | C5: 18451.273
A6: Office Supplies | B6: 719047.03 | C6: 122490.8
A7: Technology | B7: 836154.03 | C7: 145454.95

Sheet Менеджеры
A2: Проффит-Сейлс по региональным менеджерам
B3: Данные
A4: Названия строк | B4: Сумма по полю Sales | C4: Сумма по полю Profit
A5: Anna Andreadi | B5: 725457.82 | C5: 108418.45
A6: Cassandra Brandow | B6: 391721.91 | C6: 46749.43
A7: Chuck Magee | B7: 678781.24 | C7: 91522.78
A8: Kelly Williams | B8: 501239.89 | C8: 39706.362

Sheet Сегменты
A2: Проффит-Сейлс по сегментам
B3: Данные
A4: Названия строк | B4: Сумма по полю Sales | C4: Сумма по полю Profit
A5: Consumer | B5: 1161401.3 | C5: 134119.21
A6: Corporate | B6: 706146.37 | C6: 91979.134
A7: Home Office | B7: 429653.15 | C7: 60298.679

Sheet Общие показатели
A2: Проффит-Сейлс по сегментам
C3: Данные
A4: Годы | B4: Месяц | C4: Сумма по полю Sales | D4: Сумма по полю Profit | E4: Сумма по полю Profit Ratio | F4: Среднее по полю Discount
A5: 2016 | B5: янв | C5: 14236.895 | D5: 2450.1907 | E5: 0.17210148 | F5: 0.12658228
A6: 2016 | B6: фев | C6: 4519.892 | D6: 862.3084 | E6: 0.19078075 | F6: 0.17608696
A7: 2016 | B7: мар | C7: 55691.009 | D7: 498.7299 | E7: 0.0089553037 | F7: 0.16751592
A8: 2016 | B8: апр | C8: 28295.345 | D8: 3488.8352 | E8: 0.12330068 | F8: 0.11
A9: 2016 | B9: май | C9: 23648.287 | D9: 2738.7096 | E9: 0.11581006 | F9: 0.15532787
A10: 2016 | B10: июн | C10: 34595.128 | D10: 4976.5244 | E10: 0.14385044 | F10: 0.172
A11: 2016 | B11: июл | C11: 33946.393 | D11: -841.4826 | E11: -0.024788572 | F11: 0.17167832
A12: 2016 | B12: авг | C12: 27909.468 | D12: 5318.105 | E12: 0.19054842 | F12: 0.13104575
A13: 2016 | B13: сен | C13: 81777.351 | D13: 8328.0994 | E13: 0.1018387 | F13: 0.15996269
A14: 2016 | B14: окт | C14: 31453.393 | D14: 3448.2573 | E14: 0.10963069 | F14: 0.16006289
A15: 2016 | B15: ноя | C15: 78628.717 | D15: 9292.1269 | E15: 0.11817727 | F15: 0.15116352
A16: 2016 | B16: дек | C16: 69545.62 | D16: 8983.5699 | E16: 0.12917521 | F16: 0.19082734
... A52: 2019 | B52: дек | C52: 83829.319 | D52: 8483.3468 | E52: 0.10119785 | F52: 0.14658009

Sheet Динамика сегменты
A2: Проффит-Сейлс по сегментам
A3: Сумма по полю Sales | B3: Названия столбцов
A4: Названия строк | B4: Consumer | C4: Corporate | D4: Home Office
A5: 2016 | B5: 266096.81 | C5: 128434.87 | D5: 89715.812
A6: 2017 | B6: 266535.93 | C6: 128757.31 | D6: 75239.269
A7: 2018 | B7: 296863.9 | C7: 207106.36 | D7: 105235.34
A8: 2019 | B8: 331904.7 | C8: 241847.82 | D8: 159462.73

Sheet Штаты
A1: Продажи по штатам
A2: Сумма по полю Sales
A3: Country | B3: State | C3: Итог
A4: United States | B4: California | C4: 457687.63
A5: United States | B5: New York | C5: 310876.27
A6: United States | B6: Texas | C6: 170188.05
A7: United States | B7: Washington | C7: 138641.27
A8: United States | B8: Pennsylvania | C8: 116511.91
A9: United States | B9: Florida | C9: 89473.708
A10: United States | B10: Illinois | C10: 80166.101
A11: United States | B11: Ohio | C11: 78258.136
A12: United States | B12: Michigan | C12: 76269.614
A13: United States | B13: Virginia | C13: 70636.72
A14: United States | B14: North Carolina | C14: 55603.164
A15: United States | B15: Indiana | C15: 53555.36
... A52: United States | B52: North Dakota | C52: 919.91

Sheet Регион
A2: Продажи по регионам
A3: Сумма по полю Sales
A4: Названия строк | B4: Итог
A5: Central | B5: 501239.89
A6: East | B6: 678781.24
A7: South | B7: 391721.91
A8: West | B8: 725457.82

Sheet Возврат
A2: Продажи по регионам
A3: Сумма по полю Sales
A4: Названия строк | B4: Итог
A5: No | B5: 0.92142425
A6: Yes | B6: 0.078575749
A7: Общий итог | B7: 1
